<?xml version="1.0" ?>
<!-- =================================================================================== -->
<!-- |    This document was autogenerated by xacro from quadruped.urdf.xacro           | -->
<!-- |    EDITING THIS FILE BY HAND IS NOT RECOMMENDED                                 | -->
<!-- =================================================================================== -->
<robot name="quadruped">
  <material name="aluminum">
    <color rgba="0.5 0.5 0.5 1"/>
  </material>
  <material name="plastic">
    <color rgba="0.1 0.1 0.1 1"/>
  </material>
  <link name="base_link">
    <visual>
      <origin rpy="0 0 0" xyz="0 0 0"/>
      <geometry>
        <mesh filename="package://test_config/meshes/base.stl" scale="0.001 0.001 0.001"/>
      </geometry>
    </visual>
    <collision>
      <origin rpy="0 0 0" xyz="0 0 0"/>
      <geometry>
        <mesh filename="package://test_config/meshes/base.stl" scale="0.001 0.001 0.001"/>
      </geometry>
    </collision>
  </link>
  <link name="tower_link">
    <visual>
      <origin rpy="0 0 0" xyz="0 0 0"/>
      <geometry>
        <mesh filename="package://test_config/meshes/tower.stl" scale="0.001 0.001 0.001"/>
      </geometry>
    </visual>
    <collision>
      <origin rpy="0 0 0" xyz="0 0 0"/>
      <geometry>
        <mesh filename="package://test_config/meshes/tower.stl" scale="0.001 0.001 0.001"/>
      </geometry>
    </collision>
  </link>
  <!-- camera body, with origin at bottom screw mount -->
  <joint name="camera_joint" type="fixed">
    <origin rpy="0 0 0" xyz="0.075 0 0.099"/>
    <parent link="base_link"/>
    <child link="camera_bottom_screw_frame"/>
  </joint>
  <link name="camera_bottom_screw_frame"/>
  <joint name="camera_link_joint" type="fixed">
    <origin rpy="0 0 0" xyz="0.010600000000000002 0.0175 0.0125"/>
    <parent link="camera_bottom_screw_frame"/>
    <child link="camera_link"/>
  </joint>
  <link name="camera_link">
    <visual>
      <!-- the mesh origin is at front plate in between the two infrared camera axes -->
      <origin rpy="1.5707963267948966 0 1.5707963267948966" xyz="0.0043 -0.0175 0"/>
      <geometry>
        <mesh filename="package://realsense2_description/meshes/d435.dae"/>
      </geometry>
    </visual>
    <collision>
      <origin rpy="0 0 0" xyz="0 -0.0175 0"/>
      <geometry>
        <box size="0.02505 0.09 0.025"/>
      </geometry>
    </collision>
    <inertial>
      <!-- The following are not reliable values, and should not be used for modeling -->
      <mass value="0.072"/>
      <origin xyz="0 0 0"/>
      <inertia ixx="0.003881243" ixy="0.0" ixz="0.0" iyy="0.000498940" iyz="0.0" izz="0.003879257"/>
    </inertial>
  </link>
  <link name="f_bumper_link">
    <visual>
      <origin rpy="0 0 0" xyz="0 0 0"/>
      <geometry>
        <mesh filename="package://test_config/meshes/bumper.stl" scale="0.001 0.001 0.001"/>
      </geometry>
    </visual>
    <collision>
      <origin rpy="0 0 0" xyz="0 0 0"/>
      <geometry>
        <mesh filename="package://test_config/meshes/bumper.stl" scale="0.001 0.001 0.001"/>
      </geometry>
    </collision>
  </link>
  <link name="h_bumper_link">
    <visual>
      <origin rpy="0 0 3.1415" xyz="0 0 0"/>
      <geometry>
        <mesh filename="package://test_config/meshes/bumper.stl" scale="0.001 0.001 0.001"/>
      </geometry>
    </visual>
    <collision>
      <origin rpy="0 0 3.1415" xyz="0 0 0"/>
      <geometry>
        <mesh filename="package://test_config/meshes/bumper.stl" scale="0.001 0.001 0.001"/>
      </geometry>
    </collision>
  </link>
  <link name="lf_hip_link">
    <visual>
      <origin rpy="0 0 0" xyz="0 0 0"/>
      <geometry>
        <mesh filename="package://test_config/meshes/hip.stl" scale="0.001 0.001 0.001"/>
      </geometry>
    </visual>
    <collision>
      <origin rpy="0 0 0" xyz="0 0 0"/>
      <geometry>
        <mesh filename="package://test_config/meshes/hip.stl" scale="0.001 0.001 0.001"/>
      </geometry>
    </collision>
  </link>
  <link name="lf_upper_leg_link">
    <visual>
      <origin rpy="1.5707 0 3.1415" xyz="0 0 0"/>
      <geometry>
        <mesh filename="package://test_config/meshes/upper-leg.stl" scale="0.001 0.001 0.001"/>
      </geometry>
    </visual>
    <collision>
      <origin rpy="1.5707 0 3.1415" xyz="0 0 0"/>
      <geometry>
        <mesh filename="package://test_config/meshes/upper-leg.stl" scale="0.001 0.001 0.001"/>
      </geometry>
    </collision>
  </link>
  <link name="lf_lower_leg_link">
    <visual>
      <origin rpy="1.5707 0 0" xyz="0 0 0"/>
      <geometry>
        <mesh filename="package://test_config/meshes/lower-leg.stl" scale="0.001 0.001 0.001"/>
      </geometry>
    </visual>
    <collision>
      <origin rpy="1.5707 0 0" xyz="0 0 0"/>
      <geometry>
        <mesh filename="package://test_config/meshes/lower-leg.stl" scale="0.001 0.001 0.001"/>
      </geometry>
    </collision>
  </link>
  <link name="lf_foot_link">
    <visual>
      <origin rpy="1.5707 0 0" xyz="0 0 0"/>
      <geometry>
        <mesh filename="package://test_config/meshes/foot.stl" scale="0.001 0.001 0.001"/>
      </geometry>
    </visual>
    <collision>
      <origin rpy="1.5707 0 0" xyz="0 0 0"/>
      <geometry>
        <mesh filename="package://test_config/meshes/foot.stl" scale="0.001 0.001 0.001"/>
      </geometry>
    </collision>
  </link>
  <link name="rf_hip_link">
    <visual>
      <origin rpy="0 0 0" xyz="0 0 0"/>
      <geometry>
        <mesh filename="package://test_config/meshes/hip.stl" scale="0.001 -0.001 0.001"/>
      </geometry>
    </visual>
    <collision>
      <origin rpy="0 0 0" xyz="0 0 0"/>
      <geometry>
        <mesh filename="package://test_config/meshes/hip.stl" scale="0.001 -0.001 0.001"/>
      </geometry>
    </collision>
  </link>
  <link name="rf_upper_leg_link">
    <visual>
      <origin rpy="4.7123 0 3.1415" xyz="0 0 0"/>
      <geometry>
        <mesh filename="package://test_config/meshes/upper-leg.stl" scale="0.001 -0.001 0.001"/>
      </geometry>
    </visual>
    <collision>
      <origin rpy="4.7123 0 3.1415" xyz="0 0 0"/>
      <geometry>
        <mesh filename="package://test_config/meshes/upper-leg.stl" scale="0.001 -0.001 0.001"/>
      </geometry>
    </collision>
  </link>
  <link name="rf_lower_leg_link">
    <visual>
      <origin rpy="4.7123 0 0" xyz="0 0 0"/>
      <geometry>
        <mesh filename="package://test_config/meshes/lower-leg.stl" scale="0.001 -0.001 0.001"/>
      </geometry>
    </visual>
    <collision>
      <origin rpy="4.7123 0 0" xyz="0 0 0"/>
      <geometry>
        <mesh filename="package://test_config/meshes/lower-leg.stl" scale="0.001 -0.001 0.001"/>
      </geometry>
    </collision>
  </link>
  <link name="rf_foot_link">
    <visual>
      <origin rpy="4.7123 0 0" xyz="0 0 0"/>
      <geometry>
        <mesh filename="package://test_config/meshes/foot.stl" scale="0.001 -0.001 0.001"/>
      </geometry>
    </visual>
    <collision>
      <origin rpy="4.7123 0 0" xyz="0 0 0"/>
      <geometry>
        <mesh filename="package://test_config/meshes/foot.stl" scale="0.001 -0.001 0.001"/>
      </geometry>
    </collision>
  </link>
  <link name="lh_hip_link">
    <visual>
      <origin rpy="0 0 0" xyz="0 0 0"/>
      <geometry>
        <mesh filename="package://test_config/meshes/hip.stl" scale="-0.001 0.001 0.001"/>
      </geometry>
    </visual>
    <collision>
      <origin rpy="0 0 0" xyz="0 0 0"/>
      <geometry>
        <mesh filename="package://test_config/meshes/hip.stl" scale="-0.001 0.001 0.001"/>
      </geometry>
    </collision>
  </link>
  <link name="lh_upper_leg_link">
    <visual>
      <origin rpy="1.5707 0 3.1415" xyz="0 0 0"/>
      <geometry>
        <mesh filename="package://test_config/meshes/upper-leg.stl" scale="0.001 0.001 0.001"/>
      </geometry>
    </visual>
    <collision>
      <origin rpy="1.5707 0 3.1415" xyz="0 0 0"/>
      <geometry>
        <mesh filename="package://test_config/meshes/upper-leg.stl" scale="0.001 0.001 0.001"/>
      </geometry>
    </collision>
  </link>
  <link name="lh_lower_leg_link">
    <visual>
      <origin rpy="1.5707 0 0" xyz="0 0 0"/>
      <geometry>
        <mesh filename="package://test_config/meshes/lower-leg.stl" scale="0.001 0.001 0.001"/>
      </geometry>
    </visual>
    <collision>
      <origin rpy="1.5707 0 0" xyz="0 0 0"/>
      <geometry>
        <mesh filename="package://test_config/meshes/lower-leg.stl" scale="0.001 0.001 0.001"/>
      </geometry>
    </collision>
  </link>
  <link name="lh_foot_link">
    <visual>
      <origin rpy="1.5707 0 0" xyz="0 0 0"/>
      <geometry>
        <mesh filename="package://test_config/meshes/foot.stl" scale="0.001 0.001 0.001"/>
      </geometry>
    </visual>
    <collision>
      <origin rpy="1.5707 0 0" xyz="0 0 0"/>
      <geometry>
        <mesh filename="package://test_config/meshes/foot.stl" scale="0.001 0.001 0.001"/>
      </geometry>
    </collision>
  </link>
  <link name="rh_hip_link">
    <visual>
      <origin rpy="0 0 0" xyz="0 0 0"/>
      <geometry>
        <mesh filename="package://test_config/meshes/hip.stl" scale="-0.001 -0.001 0.001"/>
      </geometry>
    </visual>
    <collision>
      <origin rpy="0 0 0" xyz="0 0 0"/>
      <geometry>
        <mesh filename="package://test_config/meshes/hip.stl" scale="-0.001 -0.001 0.001"/>
      </geometry>
    </collision>
  </link>
  <link name="rh_upper_leg_link">
    <visual>
      <origin rpy="4.7123 0 3.1415" xyz="0 0 0"/>
      <geometry>
        <mesh filename="package://test_config/meshes/upper-leg.stl" scale="0.001 -0.001 0.001"/>
      </geometry>
    </visual>
    <collision>
      <origin rpy="4.7123 0 3.1415" xyz="0 0 0"/>
      <geometry>
        <mesh filename="package://test_config/meshes/upper-leg.stl" scale="0.001 -0.001 0.001"/>
      </geometry>
    </collision>
  </link>
  <link name="rh_lower_leg_link">
    <visual>
      <origin rpy="4.7123 0 0" xyz="0 0 0"/>
      <geometry>
        <mesh filename="package://test_config/meshes/lower-leg.stl" scale="0.001 -0.001 0.001"/>
      </geometry>
    </visual>
    <collision>
      <origin rpy="4.7123 0 0" xyz="0 0 0"/>
      <geometry>
        <mesh filename="package://test_config/meshes/lower-leg.stl" scale="0.001 -0.001 0.001"/>
      </geometry>
    </collision>
  </link>
  <link name="rh_foot_link">
    <visual>
      <origin rpy="4.7123 0 0" xyz="0 0 0"/>
      <geometry>
        <mesh filename="package://test_config/meshes/foot.stl" scale="0.001 -0.001 0.001"/>
      </geometry>
    </visual>
    <collision>
      <origin rpy="4.7123 0 0" xyz="0 0 0"/>
      <geometry>
        <mesh filename="package://test_config/meshes/foot.stl" scale="0.001 -0.001 0.001"/>
      </geometry>
    </collision>
  </link>
  <joint name="tower_joint" type="fixed">
    <origin rpy="0 0 0" xyz="0.0056 0.0068 0.10042"/>
    <parent link="base_link"/>
    <child link="tower_link"/>
  </joint>
  <joint name="f_bumper_joint" type="fixed">
    <origin rpy="0 0 0" xyz="0.1203 0.0000 -0.0042"/>
    <parent link="base_link"/>
    <child link="f_bumper_link"/>
  </joint>
  <joint name="h_bumper_joint" type="fixed">
    <origin rpy="0 0 0" xyz="-0.1199 0.0000 -0.0042"/>
    <parent link="base_link"/>
    <child link="h_bumper_link"/>
  </joint>
  <joint name="lf_hip_joint" type="revolute">
    <origin rpy="0 0 0" xyz="0.1105 0.0716 0.0009"/>
    <parent link="base_link"/>
    <child link="lf_hip_link"/>
    <axis xyz="1 0 0"/>
    <limit effort="25" lower="-0.8726" upper="0.8726" velocity="1.5"/>
  </joint>
  <joint name="lf_upper_leg_joint" type="revolute">
    <origin rpy="0 0 0" xyz="0.0000 0.0355 0.0041"/>
    <parent link="lf_hip_link"/>
    <child link="lf_upper_leg_link"/>
    <axis xyz="0 1 0"/>
    <limit effort="25" lower="-1.0472" upper="1.0472" velocity="1.5"/>
  </joint>
  <joint name="lf_lower_leg_joint" type="revolute">
    <origin rpy="0 0 0" xyz="0.0002 0.0003 -0.1078"/>
    <parent link="lf_upper_leg_link"/>
    <child link="lf_lower_leg_link"/>
    <axis xyz="0 1 0"/>
    <limit effort="25" lower="-2.0944" upper="-1.0472" velocity="1.5"/>
  </joint>
  <joint name="lf_foot_joint" type="fixed">
    <origin rpy="0 0 0" xyz="-0.0093 -0.0003 -0.1060"/>
    <parent link="lf_lower_leg_link"/>
    <child link="lf_foot_link"/>
  </joint>
  <joint name="rf_hip_joint" type="revolute">
    <origin rpy="0 0 0" xyz="0.1105 -0.0716 0.0009"/>
    <parent link="base_link"/>
    <child link="rf_hip_link"/>
    <axis xyz="1 0 0"/>
    <limit effort="25" lower="-0.8726" upper="0.8726" velocity="1.5"/>
  </joint>
  <joint name="rf_upper_leg_joint" type="revolute">
    <origin rpy="0 0 0" xyz="0.0000 -0.0355 0.0041"/>
    <parent link="rf_hip_link"/>
    <child link="rf_upper_leg_link"/>
    <axis xyz="0 1 0"/>
    <limit effort="25" lower="-1.0472" upper="1.0472" velocity="1.5"/>
  </joint>
  <joint name="rf_lower_leg_joint" type="revolute">
    <origin rpy="0 0 0" xyz="0.0002 -0.0003 -0.1078"/>
    <parent link="rf_upper_leg_link"/>
    <child link="rf_lower_leg_link"/>
    <axis xyz="0 1 0"/>
    <limit effort="25" lower="-2.0944" upper="-1.0472" velocity="1.5"/>
  </joint>
  <joint name="rf_foot_joint" type="fixed">
    <origin rpy="0 0 0" xyz="-0.0093 -0.0003 -0.1060"/>
    <parent link="rf_lower_leg_link"/>
    <child link="rf_foot_link"/>
  </joint>
  <joint name="lh_hip_joint" type="revolute">
    <origin rpy="0 0 0" xyz="-0.1131 0.0716 0.0009"/>
    <parent link="base_link"/>
    <child link="lh_hip_link"/>
    <axis xyz="1 0 0"/>
    <limit effort="25" lower="-0.8726" upper="0.8726" velocity="1.5"/>
  </joint>
  <joint name="lh_upper_leg_joint" type="revolute">
    <origin rpy="0 0 0" xyz="0.0000 0.0355 0.0041"/>
    <parent link="lh_hip_link"/>
    <child link="lh_upper_leg_link"/>
    <axis xyz="0 1 0"/>
    <limit effort="25" lower="-1.0472" upper="1.0472" velocity="1.5"/>
  </joint>
  <joint name="lh_lower_leg_joint" type="revolute">
    <origin rpy="0 0 0" xyz="0.0002 0.0003 -0.1078"/>
    <parent link="lh_upper_leg_link"/>
    <child link="lh_lower_leg_link"/>
    <axis xyz="0 1 0"/>
    <limit effort="25" lower="-2.0944" upper="-1.0472" velocity="1.5"/>
  </joint>
  <joint name="lh_foot_joint" type="fixed">
    <origin rpy="0 0 0" xyz="-0.0093 -0.0003 -0.1060"/>
    <parent link="lh_lower_leg_link"/>
    <child link="lh_foot_link"/>
  </joint>
  <joint name="rh_hip_joint" type="revolute">
    <origin rpy="0 0 0" xyz="-0.1131 -0.0716 0.0009"/>
    <parent link="base_link"/>
    <child link="rh_hip_link"/>
    <axis xyz="1 0 0"/>
    <limit effort="25" lower="-0.8726" upper="0.8726" velocity="1.5"/>
  </joint>
  <joint name="rh_upper_leg_joint" type="revolute">
    <origin rpy="0 0 0" xyz="0.0000 -0.0355 0.0041"/>
    <parent link="rh_hip_link"/>
    <child link="rh_upper_leg_link"/>
    <axis xyz="0 1 0"/>
    <limit effort="25" lower="-1.0472" upper="1.0472" velocity="1.5"/>
  </joint>
  <joint name="rh_lower_leg_joint" type="revolute">
    <origin rpy="0 0 0" xyz="0.0002 -0.0003 -0.1078"/>
    <parent link="rh_upper_leg_link"/>
    <child link="rh_lower_leg_link"/>
    <axis xyz="0 1 0"/>
    <limit effort="25" lower="-2.0944" upper="-1.0472" velocity="1.5"/>
  </joint>
  <joint name="rh_foot_joint" type="fixed">
    <origin rpy="0 0 0" xyz="-0.0093 -0.0003 -0.1060"/>
    <parent link="rh_lower_leg_link"/>
    <child link="rh_foot_link"/>
  </joint>
</robot>

